Workbook

Sheet Summary
A1: Amandla group - SARS cashflow projection, November 2026 to April 2027
A2: Prepared by Creative CFO, 26 October 2026, from the SARS statements of account (issued 26 Oct 2026), the Xero VAT201 screens and the Xero P&L / balance sheet to September 2026. Positive = cash paid to SARS, (negative) = cash received from SARS. Amounts in Rand. Blue inputs live on the Assumptions tab.
A4: Line | B4: When it is paid / received | C4: Oct 2026 (rest of month) | D4: Nov 2026 | E4: Dec 2026 | F4: Jan 2027 | G4: Feb 2027 | H4: Mar 2027 | I4: Apr 2027 | J4: Total Nov-Apr | K4: Basis
A5: Safe Hub NPC
A6: EMP201: PAYE + SDL + UIF less ETI | B6: By the 7th: 6 Nov, 7 Dec, 7 Jan, 5 Feb, 5 Mar, 7 Apr (pays the previous month's payroll) | C6: 0 | D6: =Assumptions!$B$16+Assumptions!$B$17+Assumptions!$B$18-Assumptions!$B$19 -> 125326.73 | E6: =Assumptions!$B$16+Assumptions!$B$17+Assumptions!$B$18-Assumptions!$B$19 -> 125326.73 | F6: =Assumptions!$B$16*Assumptions!$B$20+Assumptions!$B$17+Assumptions!$B$18-Assumptions!$B$19 -> 315845.15 | G6: =Assumptions!$B$16+Assumptions!$B$17+Assumptions!$B$18-Assumptions!$B$19 -> 125326.73 | H6: =Assumptions!$B$16+Assumptions!$B$17+Assumptions!$B$18-Assumptions!$B$19 -> 125326.73 | I6: =Assumptions!$B$16+Assumptions!$B$17+Assumptions!$B$18-Assumptions!$B$19 -> 125326.73 | J6: =SUM(D6:I6) -> 942478.8 | K6: Sep 2026 actual run-rate (PAYE R220k, ETI R139k). Jan 2027 carries the December bonus payroll (Dec-25 PAYE was 1.87x Nov-25). Sep paid 7 Oct.
A7: ETI refund from SARS (Mar-Aug 2026 cycle) | B7: Expected ~10 Dec 2026, after the EMP501 (due 31 Oct) is filed and verified | C7: 0 | D7: =IF(Assumptions!$B$39=1,-Assumptions!$B$38,0) -> 0 | E7: =IF(Assumptions!$B$39=2,-Assumptions!$B$38,0) -> -505106.68 | F7: =IF(Assumptions!$B$39=3,-Assumptions!$B$38,0) -> 0 | G7: =IF(Assumptions!$B$39=4,-Assumptions!$B$38,0) -> 0 | H7: =IF(Assumptions!$B$39=5,-Assumptions!$B$38,0) -> 0 | I7: =IF(Assumptions!$B$39=6,-Assumptions!$B$38,0) -> 0 | J7: =SUM(D7:I7) -> -505106.68 | K7: R505,106.68 per SARS statement. Last year's cycle was paid 10 Dec 2025. Not paid until the EMP501 is in; a verification can push it to January.
A8: VAT201 (bi-monthly: Sep-Oct, Nov-Dec, Jan-Feb) | B8: Last business day: 30 Nov, 29 Jan, 31 Mar (file by the 25th). Jul-Aug was paid 7 Oct. | C8: 0 | D8: =Assumptions!$B$49 -> 461743.84 | E8: 0 | F8: =Assumptions!$B$50 -> 407750.93 | G8: 0 | H8: =Assumptions!$B$51 -> 407750.93 | I8: 0 | J8: =SUM(D8:I8) -> 1277245.7 | K8: Sep-Oct: Xero to date R268k plus the Oct recharge (~R194k). Nov-Dec and Jan-Feb: trailing 3-return average R408k. Output VAT on the salary recharge to Amandla.
A9: Net Safe Hub NPC | C9: =SUM(C6:C8) -> 0 | D9: =SUM(D6:D8) -> 587070.57 | E9: =SUM(E6:E8) -> -379779.95 | F9: =SUM(F6:F8) -> 723596.08 | G9: =SUM(G6:G8) -> 125326.73 | H9: =SUM(H6:H8) -> 533077.66 | I9: =SUM(I6:I8) -> 125326.73 | J9: =SUM(D9:I9) -> 1714617.8
A11: Safe Hub Enterprises (Pty) Ltd (VAT only, no payroll)
A12: VAT201 Aug-Sep 2026 (filed 26 Oct) | B12: Pay by Fri 30 Oct 2026 via eFiling | C12: =Assumptions!$B$61 -> 191492.58 | D12: 0 | E12: 0 | F12: 0 | G12: 0 | H12: 0 | I12: 0 | J12: =SUM(D12:I12) -> 0 | K12: R191,492.58 per SARS statement. Xero shows R375,052.08 for the same period: reconcile before paying. The R19,149 penalty on the statement falls away if paid by 30 Oct.
A13: Late-payment penalty on Aug-Sep if not paid by 30 Oct | B13: Only if the 30 Oct deadline is missed | C13: =IF(Assumptions!$B$63=1,0,Assumptions!$B$62) -> 0 | D13: 0 | E13: 0 | F13: 0 | G13: 0 | H13: 0 | I13: 0 | J13: =SUM(D13:I13) -> 0 | K13: 10% of the return, plus interest from 1 Nov. Switch on the Assumptions tab.
A14: VAT201 (bi-monthly: Oct-Nov, Dec-Jan, Feb-Mar) | B14: Last business day: 31 Dec, 26 Feb, 30 Apr (file by the 25th) | C14: 0 | D14: 0 | E14: =Assumptions!$B$64 -> 650000 | F14: 0 | G14: =Assumptions!$B$65 -> 121844.86 | H14: 0 | I14: =Assumptions!$B$66 -> 753994.26 | J14: =SUM(D14:I14) -> 1525839.1 | K14: Oct-Nov: R650k judgement (last year R1.14m incl. a once-off R3m invoice). Dec-Jan: last year R122k. Feb-Mar: last year R754k. Moves 1:1 with funder invoicing.
A15: Net Safe Hub Enterprises | C15: =SUM(C12:C14) -> 191492.58 | D15: =SUM(D12:D14) -> 0 | E15: =SUM(E12:E14) -> 650000 | F15: =SUM(F12:F14) -> 0 | G15: =SUM(G12:G14) -> 121844.86 | H15: =SUM(H12:H14) -> 0 | I15: =SUM(I12:I14) -> 753994.26 | J15: =SUM(D15:I15) -> 1525839.1
A17: Amandla Social Enterprises
A18: EMP201: PAYE + UIF less ETI (no SDL) | B18: By the 7th: 6 Nov, 7 Dec, 7 Jan, 5 Feb, 5 Mar, 7 Apr (pays the previous month's payroll) | C18: 0 | D18: =Assumptions!$B$31+Assumptions!$B$32+Assumptions!$B$33-Assumptions!$B$34 -> 573161.79 | E18: =Assumptions!$B$31+Assumptions!$B$32+Assumptions!$B$33-Assumptions!$B$34 -> 573161.79 | F18: =Assumptions!$B$31*Assumptions!$B$35+Assumptions!$B$32+Assumptions!$B$33-Assumptions!$B$34 -> 961631.55 | G18: =Assumptions!$B$31+Assumptions!$B$32+Assumptions!$B$33-Assumptions!$B$34 -> 573161.79 | H18: =Assumptions!$B$31+Assumptions!$B$32+Assumptions!$B$33-Assumptions!$B$34 -> 573161.79 | I18: =Assumptions!$B$31+Assumptions!$B$32+Assumptions!$B$33-Assumptions!$B$34 -> 573161.79 | J18: =SUM(D18:I18) -> 3827440.5 | K18: Sep 2026 actual run-rate (PAYE R606k, ETI R56k, net R573k). Jan 2027 carries the December bonus payroll (Dec-25 PAYE was 1.64x Nov-25). Sep paid 7 Oct.
A19: VAT201 refunds (monthly) | B19: Filed by the 25th of the following month; SARS usually pays within a week of filing | C19: 0 | D19: =-IF(Assumptions!$B$81=0,Assumptions!$B$75,IF(1-Assumptions!$B$81>=1,INDEX(Assumptions!$B:$B,ROW(Assumptions!$B$75)+1-1-Assumptions!$B$81),0)) -> -522963.63 | E19: =-IF(Assumptions!$B$81=0,Assumptions!$B$76,IF(2-Assumptions!$B$81>=1,INDEX(Assumptions!$B:$B,ROW(Assumptions!$B$75)+2-1-Assumptions!$B$81),0)) -> -522963.63 | F19: =-IF(Assumptions!$B$81=0,Assumptions!$B$77,IF(3-Assumptions!$B$81>=1,INDEX(Assumptions!$B:$B,ROW(Assumptions!$B$75)+3-1-Assumptions!$B$81),0)) -> -522963.63 | G19: =-IF(Assumptions!$B$81=0,Assumptions!$B$78,IF(4-Assumptions!$B$81>=1,INDEX(Assumptions!$B:$B,ROW(Assumptions!$B$75)+4-1-Assumptions!$B$81),0)) -> -522963.63 | H19: =-IF(Assumptions!$B$81=0,Assumptions!$B$79,IF(5-Assumptions!$B$81>=1,INDEX(Assumptions!$B:$B,ROW(Assumptions!$B$75)+5-1-Assumptions!$B$81),0)) -> -522963.63 | I19: =-IF(Assumptions!$B$81=0,Assumptions!$B$80,IF(6-Assumptions!$B$81>=1,INDEX(Assumptions!$B:$B,ROW(Assumptions!$B$75)+6-1-Assumptions!$B$81),0)) -> -522963.63 | J19: =SUM(D19:I19) -> -3137781.8 | K19: Trailing 6-month average refund R523k per month (Jul-Sep ran at R610k). 2 of the last 12 refunds were held ~4 weeks for verification; the delay switch on Assumptions shifts all refunds a month later.
A20: Net Amandla Social Enterprises | C20: =SUM(C18:C19) -> 0 | D20: =SUM(D18:D19) -> 50198.16 | E20: =SUM(E18:E19) -> 50198.16 | F20: =SUM(F18:F19) -> 438667.92 | G20: =SUM(G18:G19) -> 50198.16 | H20: =SUM(H18:H19) -> 50198.16 | I20: =SUM(I18:I19) -> 50198.16 | J20: =SUM(D20:I20) -> 689658.72
A22: Group
A23: Total payments to SARS | C23: =SUMIF(C6:C8,">0")+SUMIF(C12:C14,">0")+SUMIF(C18:C19,">0") -> 191492.58 | D23: =SUMIF(D6:D8,">0")+SUMIF(D12:D14,">0")+SUMIF(D18:D19,">0") -> 1160232.4 | E23: =SUMIF(E6:E8,">0")+SUMIF(E12:E14,">0")+SUMIF(E18:E19,">0") -> 1348488.5 | F23: =SUMIF(F6:F8,">0")+SUMIF(F12:F14,">0")+SUMIF(F18:F19,">0") -> 1685227.6 | G23: =SUMIF(G6:G8,">0")+SUMIF(G12:G14,">0")+SUMIF(G18:G19,">0") -> 820333.38 | H23: =SUMIF(H6:H8,">0")+SUMIF(H12:H14,">0")+SUMIF(H18:H19,">0") -> 1106239.5 | I23: =SUMIF(I6:I8,">0")+SUMIF(I12:I14,">0")+SUMIF(I18:I19,">0") -> 1452482.8 | J23: =SUM(D23:I23) -> 7573004.1 | K23: EMP201 and VAT payments across the three entities.
A24: Total receipts from SARS | C24: =SUMIF(C6:C8,"<0")+SUMIF(C12:C14,"<0")+SUMIF(C18:C19,"<0") -> 0 | D24: =SUMIF(D6:D8,"<0")+SUMIF(D12:D14,"<0")+SUMIF(D18:D19,"<0") -> -522963.63 | E24: =SUMIF(E6:E8,"<0")+SUMIF(E12:E14,"<0")+SUMIF(E18:E19,"<0") -> -1028070.3 | F24: =SUMIF(F6:F8,"<0")+SUMIF(F12:F14,"<0")+SUMIF(F18:F19,"<0") -> -522963.63 | G24: =SUMIF(G6:G8,"<0")+SUMIF(G12:G14,"<0")+SUMIF(G18:G19,"<0") -> -522963.63 | H24: =SUMIF(H6:H8,"<0")+SUMIF(H12:H14,"<0")+SUMIF(H18:H19,"<0") -> -522963.63 | I24: =SUMIF(I6:I8,"<0")+SUMIF(I12:I14,"<0")+SUMIF(I18:I19,"<0") -> -522963.63 | J24: =SUM(D24:I24) -> -3642888.5 | K24: Amandla VAT refunds and the NPC ETI refund.
A25: Net cash to (from) SARS | C25: =C9+C15+C20 -> 191492.58 | D25: =D9+D15+D20 -> 637268.73 | E25: =E9+E15+E20 -> 320418.21 | F25: =F9+F15+F20 -> 1162264 | G25: =G9+G15+G20 -> 297369.75 | H25: =H9+H15+H20 -> 583275.82 | I25: =I9+I15+I20 -> 929519.15 | J25: =SUM(D25:I25) -> 3930115.7
A26: Cumulative from 1 Nov 2026 | C26: 0 | D26: =D25 -> 637268.73 | E26: =D26+E25 -> 957686.94 | F26: =E26+F25 -> 2119950.9 | G26: =F26+G25 -> 2417320.7 | H26: =G26+H25 -> 3000596.5 | I26: =H26+I25 -> 3930115.7
A28: Key points for Claudene and Thapelo
A29: 1. Safe Hub Enterprises must pay R191,492.58 by Friday 30 October 2026 to avoid the R19,149 penalty already showing on its statement. Reconcile against the Xero figure of R375,052.08 first.
A30: 2. The Safe Hub NPC EMP501 is due 31 October 2026. The R505,107 ETI refund will not be paid until it is filed; on last year's timing it should arrive around 10 December. This is the single biggest receipt in the forecast.
A31: 3. January 2027 is the heaviest month: the December bonus payroll lifts both EMP201s (paid 7 Jan) and the Safe Hub NPC Nov-Dec VAT falls due on 29 January.
A32: 4. Late payments cost the group roughly R330k in penalties and interest over the last 12 months (see Risks & notes). Paying EMP201 by the 7th and VAT by the last business day removes that cost entirely.
A33: 5. Amandla's VAT refunds (~R520k a month) fund most of the group's SARS payments. If SARS holds one for verification, the group net swings by that amount for a month.
A34: 6. PAYE run-rates are the September 2026 actuals. Replace them with the October payroll figures from SimplePay as soon as the payroll is run (Assumptions tab, rows highlighted yellow).

Sheet Assumptions
A1: Assumptions and inputs
A2: Blue cells are inputs you can change; the Summary recalculates. Yellow = key judgement calls. Green = pulled from the history tabs (SARS statements).
A4: 1. Horizon and payment timing
A5: EMP201 payment date (7th of the month, or the last business day before it) | B5: paid 7 Oct (done) | C5: Fri 6 Nov | D5: Mon 7 Dec | E5: Thu 7 Jan | F5: Fri 5 Feb | G5: Fri 5 Mar | H5: Wed 7 Apr | I5: EMP201 for a payroll month is paid by the 7th of the following month. Nov pays the Oct payroll, and so on.
A6: VAT201 payment date (last business day of the month after the period ends, via eFiling) | B6: Fri 30 Oct | C6: Mon 30 Nov | D6: Thu 31 Dec | E6: Fri 29 Jan | F6: Fri 26 Feb | G6: Wed 31 Mar | H6: Fri 30 Apr | I6: A VAT return filed by the 25th and paid by the last business day of that month carries no late-payment penalty. Paid after that: 10% penalty plus interest (currently 10.25% p.a.).
A8: 2. Safe Hub NPC - EMP201 (monthly)
A9: Reference (from SH NPC PAYE tab) | B9: Jul 2026 | C9: Aug 2026 | D9: Sep 2026 | E9: Avg Jul-Sep
A10: PAYE | B10: ='SH NPC PAYE'!C33 -> 101709.29 | C10: ='SH NPC PAYE'!C34 -> 143526.56 | D10: ='SH NPC PAYE'!C35 -> 220030.94 | E10: =AVERAGE(B10:D10) -> 155088.93
A11: SDL | B11: ='SH NPC PAYE'!D33 -> 15126.68 | C11: ='SH NPC PAYE'!D34 -> 16362.25 | D11: ='SH NPC PAYE'!D35 -> 18588.92 | E11: =AVERAGE(B11:D11) -> 16692.617
A12: UIF | B12: ='SH NPC PAYE'!E33 -> 25259.38 | C12: ='SH NPC PAYE'!E34 -> 25347.68 | D12: ='SH NPC PAYE'!E35 -> 25957.26 | E12: =AVERAGE(B12:D12) -> 25521.44
A13: ETI utilised | B13: ='SH NPC PAYE'!F33 -> 101709.29 | C13: ='SH NPC PAYE'!F34 -> 143526.56 | D13: ='SH NPC PAYE'!F35 -> 139250.39 | E13: =AVERAGE(B13:D13) -> 128162.08
A14: Net EMP201 paid | B14: ='SH NPC PAYE'!G33 -> 40386.06 | C14: ='SH NPC PAYE'!G34 -> 41709.93 | D14: ='SH NPC PAYE'!G35 -> 125326.73 | E14: =AVERAGE(B14:D14) -> 69140.907
A16: PAYE per month used in forecast (R) | B16: ='SH NPC PAYE'!C35 -> 220030.94 | I16: Sep 2026 actual held flat. PAYE has risen every month since staff moved across from Amandla in July (R102k Jul, R144k Aug, R220k Sep). Sep is the latest actual and the most conservative for cash. Replace with the Oct payroll figure from SimplePay once run.
A17: SDL per month (R) | B17: ='SH NPC PAYE'!D35 -> 18588.92 | I17: Sep 2026 actual held flat.
A18: UIF per month (R) | B18: ='SH NPC PAYE'!E35 -> 25957.26 | I18: Sep 2026 actual held flat (UIF is capped per employee, so it moves little).
A19: ETI calculated per month (R) | B19: ='SH NPC PAYE'!L35 -> 139250.39 | I19: Sep 2026 actual held flat. Since Aug 2026 PAYE exceeds ETI, so the full ETI is used against PAYE each month and nothing more builds up with SARS.
A20: December payroll factor on PAYE (13th cheque / bonus month) | B20: ='SH NPC PAYE'!C26/'SH NPC PAYE'!C25 -> 1.865871 | I20: Dec 2025 PAYE was 1.87x Nov 2025 (R82.6k vs R44.3k) because of the December bonus run. Applied to Dec 2026 PAYE (paid 7 Jan 2027). Set to 1.00 if no bonus is paid this year.
A21: ETI in December | B21: 1 | I21: ETI is capped per employee, so the bonus month does not increase it. (1 = same ETI as other months.)
A23: 3. Amandla Social Enterprises - EMP201 (monthly)
A24: Reference (from Amandla PAYE tab) | B24: Jul 2026 | C24: Aug 2026 | D24: Sep 2026 | E24: Avg Jul-Sep
A25: PAYE | B25: ='Amandla PAYE'!C33 -> 653302.6 | C25: ='Amandla PAYE'!C34 -> 624609.95 | D25: ='Amandla PAYE'!C35 -> 605717.96 | E25: =AVERAGE(B25:D25) -> 627876.84
A26: SDL | B26: ='Amandla PAYE'!D33 -> 0 | C26: ='Amandla PAYE'!D34 -> 0 | D26: ='Amandla PAYE'!D35 -> 0 | E26: =AVERAGE(B26:D26) -> 0
A27: UIF | B27: ='Amandla PAYE'!E33 -> 25418.02 | C27: ='Amandla PAYE'!E34 -> 24251.3 | D27: ='Amandla PAYE'!E35 -> 23159.66 | E27: =AVERAGE(B27:D27) -> 24276.327
A28: ETI utilised | B28: ='Amandla PAYE'!F33 -> 37590.83 | C28: ='Amandla PAYE'!F34 -> 63090.83 | D28: ='Amandla PAYE'!F35 -> 55715.83 | E28: =AVERAGE(B28:D28) -> 52132.497
A29: Net EMP201 paid | B29: ='Amandla PAYE'!G33 -> 641129.79 | C29: ='Amandla PAYE'!G34 -> 585770.42 | D29: ='Amandla PAYE'!G35 -> 573161.79 | E29: =AVERAGE(B29:D29) -> 600020.67
A31: PAYE per month used in forecast (R) | B31: ='Amandla PAYE'!C35 -> 605717.96 | I31: Sep 2026 actual held flat (R606k). Jul-Sep average is R628k; PAYE has eased slightly since July as staff moved to Safe Hub NPC. Replace with the Oct payroll figure from SimplePay once run.
A32: SDL per month (R) | B32: ='Amandla PAYE'!D35 -> 0 | I32: Nil: Amandla is SDL-exempt (PBO).
A33: UIF per month (R) | B33: ='Amandla PAYE'!E35 -> 23159.66 | I33: Sep 2026 actual held flat.
A34: ETI calculated per month (R) | B34: ='Amandla PAYE'!L35 -> 55715.83 | I34: Sep 2026 actual held flat (R55.7k). Always fully used against PAYE, so Amandla never builds an ETI balance and gets no cash refund; the benefit is a lower EMP201 payment.
A35: December payroll factor on PAYE (13th cheque / bonus month) | B35: ='Amandla PAYE'!C26/'Amandla PAYE'!C25 -> 1.6413377 | I35: Dec 2025 PAYE was 1.64x Nov 2025 (R868k vs R529k) because of the December bonus run. Applied to Dec 2026 PAYE (paid 7 Jan 2027). Set to 1.00 if no bonus is paid this year.
A37: 4. Safe Hub NPC - ETI cash refund
A38: ETI balance owed by SARS for the Mar-Aug 2026 cycle (R) | B38: ='SH NPC PAYE'!M34 -> 505106.68 | I38: Per SARS statement of account 26 Oct 2026: ETI 202603 to 202608 = R505,106.68. Paid out in cash after the EMP501 reconciliation (due 31 Oct 2026) is filed and any verification is closed.
A39: Month the refund is expected (1 = Nov 2026 ... 6 = Apr 2027) | B39: 2 | I39: Dec 2026, based on the last four cycles: Aug-24 cycle paid 12 Jan 2025, Feb-25 cycle paid 25 May 2025, Aug-25 cycle paid 10 Dec 2025, Feb-26 cycle paid 31 May 2026. Change to 3 to test a January receipt.
A40: Sep 2026-Feb 2027 cycle | I40: Nil expected. From Sep 2026 PAYE exceeds ETI, so the full ETI is used each month and no balance builds up. Any balance would only be paid ~June 2027, outside this horizon.
A42: 5. Safe Hub NPC - VAT201 (bi-monthly, payable)
A43: Reference (from SH NPC VAT tab) | B43: Amount
A44: Trailing average of last 3 returns (Mar-Apr, May-Jun, Jul-Aug 2026, incl. assessment) | B44: =AVERAGE('SH NPC VAT'!C17+'SH NPC VAT'!D17,'SH NPC VAT'!C18,'SH NPC VAT'!C19) -> 407750.93
A45: Same period last year: Sep-Oct 2025 / Nov-Dec 2025 / Jan-Feb 2026 | B45: ='SH NPC VAT'!C14 -> 370625.28 | C45: ='SH NPC VAT'!C15 -> 96064.46 | D45: ='SH NPC VAT'!C16 -> 373522.47
A46: Xero: Sep-Oct 2026 return to date (26 Oct 2026) | B46: 267917.74 | I46: From the Xero VAT201 screen on 26 Oct 2026. The October month-end recharge to Amandla (cost recoveries) was not yet invoiced.
A47: Output VAT on one month of recharges at the Sep 2026 level (15% x R1,292,174) | B47: =ROUND(1292174*0.15,2) -> 193826.1 | I47: Sep 2026 cost recoveries from related parties per the Xero P&L. NPC VAT is essentially output VAT on the salary recharge to Amandla, with small inputs.
...

Sheet Risks & notes
A1: Risks, sensitivities and the cost of paying late
A3: Penalties and interest charged by SARS in the last 12 months (periods Oct 2025 to Sep 2026)
A4: Entity / tax | B4: Penalties | C4: Interest | D4: Total | E4: Periods affected | F4: Note
A5: Safe Hub NPC - VAT | B5: =SUM('SH NPC VAT'!E14,'SH NPC VAT'!E15,'SH NPC VAT'!E16,'SH NPC VAT'!E17,'SH NPC VAT'!E18,'SH NPC VAT'!E19) -> 79806.59 | C5: =SUM('SH NPC VAT'!F14,'SH NPC VAT'!F15,'SH NPC VAT'!F16,'SH NPC VAT'!F17,'SH NPC VAT'!F18,'SH NPC VAT'!F19) -> 4693.64 | D5: =B5+C5 -> 84500.23 | E5: Oct 2025, Dec 2025, Feb 2026, Apr 2026, Jun 2026, Aug 2026 | F5: Sep-Oct 2025 and Jul-Aug 2026 paid after the deadline; Mar-Apr 2026 had an additional assessment.
A6: Safe Hub NPC - PAYE | B6: =SUM('SH NPC PAYE'!H24,'SH NPC PAYE'!H25,'SH NPC PAYE'!H26,'SH NPC PAYE'!H27,'SH NPC PAYE'!H28,'SH NPC PAYE'!H29,'SH NPC PAYE'!H30,'SH NPC PAYE'!H31,'SH NPC PAYE'!H32,'SH NPC PAYE'!H33,'SH NPC PAYE'!H34,'SH NPC PAYE'!H35) -> 0 | C6: =SUM('SH NPC PAYE'!I24,'SH NPC PAYE'!I25,'SH NPC PAYE'!I26,'SH NPC PAYE'!I27,'SH NPC PAYE'!I28,'SH NPC PAYE'!I29,'SH NPC PAYE'!I30,'SH NPC PAYE'!I31,'SH NPC PAYE'!I32,'SH NPC PAYE'!I33,'SH NPC PAYE'!I34,'SH NPC PAYE'!I35) -> 0 | D6: =B6+C6 -> 0 | E6: Oct 2025, Nov 2025, Dec 2025, Jan 2026, Feb 2026, Mar 2026, Apr 2026, May 2026, Jun 2026, Jul 2026, Aug 2026, Sep 2026 | F6: All paid on time in the last 12 months. Aug-Sep 2025 were paid late (Dec 2025) and cost R18.6k, just outside the window.
A7: Safe Hub Enterprises - VAT | B7: =SUM('SH Enterprises VAT'!E15,'SH Enterprises VAT'!E16,'SH Enterprises VAT'!E17,'SH Enterprises VAT'!E18,'SH Enterprises VAT'!E19,'SH Enterprises VAT'!E20) -> 133632.03 | C7: =SUM('SH Enterprises VAT'!F15,'SH Enterprises VAT'!F16,'SH Enterprises VAT'!F17,'SH Enterprises VAT'!F18,'SH Enterprises VAT'!F19,'SH Enterprises VAT'!F20) -> 47354.24 | D7: =B7+C7 -> 180986.27 | E7: Nov 2025, Jan 2026, Mar 2026, May 2026, Jul 2026, Sep 2026 | F7: Oct-Nov 2025 (R1.14m) was paid in six instalments from Feb to Jul 2026 and cost R162k. The R19.1k on Aug-Sep 2026 falls away if paid by 30 Oct.
A8: Amandla - PAYE | B8: =SUM('Amandla PAYE'!H24,'Amandla PAYE'!H25,'Amandla PAYE'!H26,'Amandla PAYE'!H27,'Amandla PAYE'!H28,'Amandla PAYE'!H29,'Amandla PAYE'!H30,'Amandla PAYE'!H31,'Amandla PAYE'!H32,'Amandla PAYE'!H33,'Amandla PAYE'!H34,'Amandla PAYE'!H35) -> 58577.04 | C8: =SUM('Amandla PAYE'!I24,'Amandla PAYE'!I25,'Amandla PAYE'!I26,'Amandla PAYE'!I27,'Amandla PAYE'!I28,'Amandla PAYE'!I29,'Amandla PAYE'!I30,'Amandla PAYE'!I31,'Amandla PAYE'!I32,'Amandla PAYE'!I33,'Amandla PAYE'!I34,'Amandla PAYE'!I35) -> 4935.24 | D8: =B8+C8 -> 63512.28 | E8: Oct 2025, Nov 2025, Dec 2025, Jan 2026, Feb 2026, Mar 2026, Apr 2026, May 2026, Jun 2026, Jul 2026, Aug 2026, Sep 2026 | F8: Aug 2026 paid a month late (7 Oct). 2024-25 arrears were settled by SARS setting off VAT refunds; those penalties fall outside the window.
A9: Amandla - VAT | B9: =SUM('Amandla VAT'!E24,'Amandla VAT'!E25,'Amandla VAT'!E26,'Amandla VAT'!E27,'Amandla VAT'!E28,'Amandla VAT'!E29,'Amandla VAT'!E30,'Amandla VAT'!E31,'Amandla VAT'!E32,'Amandla VAT'!E33,'Amandla VAT'!E34,'Amandla VAT'!E35) -> 0 | C9: =SUM('Amandla VAT'!F24,'Amandla VAT'!F25,'Amandla VAT'!F26,'Amandla VAT'!F27,'Amandla VAT'!F28,'Amandla VAT'!F29,'Amandla VAT'!F30,'Amandla VAT'!F31,'Amandla VAT'!F32,'Amandla VAT'!F33,'Amandla VAT'!F34,'Amandla VAT'!F35) -> 0 | D9: =B9+C9 -> 0 | E9: Oct 2025, Nov 2025, Dec 2025, Jan 2026, Feb 2026, Mar 2026, Apr 2026, May 2026, Jun 2026, Jul 2026, Aug 2026, Sep 2026 | F9: Refund position; no penalties.
A10: Total | B10: =SUM(B5:B9) -> 272015.66 | C10: =SUM(C5:C9) -> 56983.12 | D10: =SUM(D5:D9) -> 328998.78
A12: Sensitivities and risks
A13: ETI refund timing | B13: R505,107 is in December. The last four cycle payouts landed 12 Jan 2025, 25 May 2025, 10 Dec 2025 and 31 May 2026. It needs the EMP501 (due 31 Oct 2026) filed and any verification answered. The ETI schedule sent on 2 Sep 2026 noted the payroll EMP501 shows R375,897 for the cycle against R505,107 on the SARS statement (May 2026 ETI of R148k vs R277k); if the EMP501 is filed at the payroll figure the refund drops by ~R129k.
A14: December bonus payroll | B14: Dec 2025 PAYE was 1.87x November at Safe Hub NPC and 1.64x at Amandla. The same factors are applied to Dec 2026 (paid 7 Jan 2027). If no bonus is paid, set the factors to 1.00 on the Assumptions tab: the January outflow falls by roughly R190k (NPC) and R390k (Amandla).
A15: Safe Hub NPC PAYE step-up | B15: PAYE went from R102k (Jul) to R144k (Aug) to R220k (Sep) as staff moved in from Amandla. September is held flat. If October settles lower, the EMP201 falls; if more staff move across it rises. Replace with the SimplePay figure once the Oct payroll is run.
A16: Amandla VAT refund verification | B16: 10 of the last 12 refunds were paid within a week of filing. Two were held about 4 weeks (Oct 2025 return paid 19 Jan 2026; Aug 2026 return paid 15 Oct 2026). A held refund delays ~R520k by a month. The delay switch on Assumptions models this.
A17: Safe Hub Enterprises VAT | B17: Output VAT is 15% of invoiced funder tranches and services; inputs are small. Oct-Nov is the historically large period (R990k in 2024, R1.14m in 2025). The R650k used assumes the recurring tranches but not the once-off R3.0m services invoice of Oct 2025. Also reconcile the Aug-Sep return: SARS R191,492.58 vs Xero R375,052.08.
A18: Safe Hub NPC VAT | B18: The NPC return is output VAT on the salary recharge to Amandla. Because the recharge moved up when staff transferred in July 2026, the trailing 3-return average (R408k) is used rather than last year's Nov-Dec (R96k) and Jan-Feb (R374k).
A19: Annual increases | B19: No salary increase is modelled. Amandla's increase month is not visible in the history (PAYE moved mainly with headcount). Add a factor to the PAYE run-rates if increases are due in the horizon.
A20: Interest on late payment | B20: SARS interest is currently 10.25% p.a. plus a 10% once-off late-payment penalty. On a R600k EMP201 that is R60k the day it is late.

Sheet SH NPC PAYE
A1: Safe Hub NPC - EMP201 history (PAYE, SDL, UIF, ETI)
A2: Source: SARS EMPSOA statements of account, taxpayer ref 7920808948, issued 2026/10/26. Net EMP201 payable = PAYE + SDL + UIF - ETI utilised. Penalties/interest are what SARS raised for late payment.
A4: Tax period | B4: Payroll month | C4: PAYE | D4: SDL | E4: UIF | F4: ETI utilised | G4: Net EMP201 payable | H4: Penalty | I4: Interest | J4: Cash paid (incl pen/int) | K4: Payment date(s) | L4: ETI calculated | M4: ETI carried forward (balance owed by SARS)
A5: 202403 | B5: Mar 2024 | C5: 45742.29 | D5: 11010.32 | E5: 20018.74 | F5: 45742.29 | G5: =C5+D5+E5-F5 -> 31029.06 | H5: 0 | I5: 0 | J5: 31029.06 | K5: 2024/04/05 | L5: 87666.83 | M5: 41924.54
A6: 202404 | B6: Apr 2024 | C6: 48545.07 | D6: 11250.83 | E6: 20501.98 | F6: 48545.07 | G6: =C6+D6+E6-F6 -> 31752.81 | H6: 2901.38 | I6: 549.56 | J6: 0 | K6: settled by journal/credit | L6: 101437.5 | M6: 94816.97
A7: 202405 | B7: May 2024 | C7: 46470.67 | D7: 11082.08 | E7: 20033.24 | F7: 0 | G7: =C7+D7+E7-F7 -> 77585.99 | H7: 7758.6 | I7: 697.43 | J7: 86042.02 | K7: 2024/07/05 | L7: 101250 | M7: 196066.97
A8: 202406 | B8: Jun 2024 | C8: 48455.4 | D8: 11253.42 | E8: 20303.58 | F8: 0 | G8: =C8+D8+E8-F8 -> 80012.4 | H8: 0 | I8: 0 | J8: 80012.4 | K8: 2024/07/05 | L8: 101062.5 | M8: 297129.47
A9: 202407 | B9: Jul 2024 | C9: 42377.22 | D9: 11103.98 | E9: 20323.28 | F9: 42377.22 | G9: =C9+D9+E9-F9 -> 31427.26 | H9: 0 | I9: 0 | J9: 31427.26 | K9: 2024/08/07 | L9: 103687.5 | M9: 358439.75
A10: 202408 | B10: Aug 2024 | C10: 45430.68 | D10: 11010.31 | E10: 20121.12 | F10: 45430.68 | G10: =C10+D10+E10-F10 -> 31131.43 | H10: 3113.14 | I10: 1257.63 | J10: 35502.2 | K10: 2025/01/10 | L10: 101329.64 | M10: 0
A11: 202409 | B11: Sep 2024 | C11: 43271.72 | D11: 10841.15 | E11: 19712.28 | F11: 0 | G11: =C11+D11+E11-F11 -> 73825.15 | H11: 7382.52 | I11: 2247.6 | J11: 83455.27 | K11: 2025/01/10 | L11: 104250 | M11: 104250
A12: 202410 | B12: Oct 2024 | C12: 43271.53 | D12: 11292.93 | E12: 20615.84 | F12: 0 | G12: =C12+D12+E12-F12 -> 75180.3 | H12: 7518.02 | I12: 1540.64 | J12: 84238.96 | K12: 2025/01/10 | L12: 114187.5 | M12: 218437.5
A13: 202411 | B13: Nov 2024 | C13: 43451.53 | D13: 11319.37 | E13: 20668.72 | F13: 0 | G13: =C13+D13+E13-F13 -> 75439.62 | H13: 7543.96 | I13: 606.09 | J13: 83589.67 | K13: 2024/12/31, 2025/01/10 | L13: 114187.5 | M13: 332625
A14: 202412 | B14: Dec 2024 | C14: 48998.2 | D14: 11048.5 | E14: 19932.14 | F14: 0 | G14: =C14+D14+E14-F14 -> 79978.84 | H14: 0 | I14: 0 | J14: 79978.84 | K14: 2025/01/07 | L14: 101418.75 | M14: 434043.75
A15: 202501 | B15: Jan 2025 | C15: 41123.39 | D15: 11240.25 | E15: 20623.14 | F15: 41123.39 | G15: =C15+D15+E15-F15 -> 31863.39 | H15: 0 | I15: 0 | J15: 31863.39 | K15: 2025/02/07 | L15: 100218.75 | M15: 493139.11
A16: 202502 | B16: Feb 2025 | C16: 41452.31 | D16: 10789.5 | E16: 19721.64 | F16: 41452.31 | G16: =C16+D16+E16-F16 -> 30511.14 | H16: 3051.11 | I16: 48.15 | J16: 33609.45 | K16: 2025/03/10, 2025/03/31 | L16: 103084.82 | M16: 0
... A35: 202609 | B35: Sep 2026 | C35: 220030.94 | D35: 18588.92 | E35: 25957.26 | F35: 139250.39 | G35: =C35+D35+E35-F35 -> 125326.73 | H35: 0 | I35: 0 | J35: 125326.73 | K35: 2026/10/07 | L35: 139250.39 | M35: 0
A37: ETI cash refunds paid by SARS (end of each 6-month cycle):
A38: 2025/01/12 | B38: cycle to Aug 2024 | C38: 414338.7
A39: 2025/05/25 | B39: cycle to Feb 2025 | C39: 554753.64
A40: 2025/12/10 | B40: cycle to Aug 2025 | C40: 502604.72
A41: 2026/05/31 | B41: cycle to Feb 2026 | C41: 471878.22

Sheet SH NPC VAT
A1: Safe Hub NPC - VAT201 history (bi-monthly, periods ending Feb/Apr/Jun/Aug/Oct/Dec)
A2: Source: SARS VATSA statements of account issued 26 Oct 2026. Positive return = VAT payable. VX references are deferred payment arrangements with SARS.
A4: Tax period (end) | B4: Period | C4: Return: payable (+) / refund (-) | D4: Additional assessment | E4: Penalty | F4: Interest | G4: Cash paid to SARS | H4: Refund received from SARS | I4: Set-off / journals | J4: Filed on | K4: Payment / refund date(s) | L4: Days from filing to cash
A5: 202404 | B5: Mar-Apr 2024 | C5: 647704.89 | D5: 0 | E5: 64770.49 | F5: 54612.95 | G5: 891539.92 | H5: 0 | I5: 124451.59 | J5: 2024/05/30 | K5: 2024/08/31, 2024/09/30, 2024/10/30, 2024/11/27, 2024/12/31, 2025/01/31, 2026/05/27 | L5: 727
A6: 202406 | B6: May-Jun 2024 | C6: 7605.12 | D6: 0 | E6: 760.51 | F6: 74.45 | G6: 8440.08 | H6: 0 | I6: 0 | J6: 2024/07/31 | K6: 2024/08/05 | L6: 5
A7: 202408 | B7: Jul-Aug 2024 | C7: 384546.33 | D7: 0 | E7: 38454.63 | F7: 26293.25 | G7: 449294.21 | H7: 0 | I7: 0 | J7: 2024/09/30 | K7: 2025/03/31, 2025/05/06 | L7: 218
A8: 202410 | B8: Sep-Oct 2024 | C8: 421682.87 | D8: 0 | E8: 42168.29 | F8: 27852.16 | G8: 491703.32 | H8: 0 | I8: 0 | J8: 2024/11/29 | K8: 2025/05/06, 2025/06/13 | L8: 196
A9: 202412 | B9: Nov-Dec 2024 | C9: 368073.63 | D9: 0 | E9: 36807.36 | F9: 17181.69 | G9: 422062.68 | H9: 0 | I9: 0 | J9: 2025/01/31 | K9: 2025/06/13 | L9: 133
A10: 202502 | B10: Jan-Feb 2025 | C10: 266221.85 | D10: 0 | E10: 0 | F10: 0 | G10: 266221.85 | H10: 0 | I10: 0 | J10: 2025/03/30 | K10: 2025/03/31 | L10: 1
A11: 202504 | B11: Mar-Apr 2025 | C11: 251991.69 | D11: 0 | E11: 25199.17 | F11: 2310.76 | G11: 279501.62 | H11: 0 | I11: 0 | J11: 2025/05/26 | K11: 2025/06/09, 2025/06/13 | L11: 18
A12: 202506 | B12: May-Jun 2025 | C12: 492299.18 | D12: 0 | E12: 49227.33 | F12: 28266.18 | G12: 569766.8 | H12: 0 | I12: -25.89 | J12: 2025/07/27 | K12: 2025/12/31, 2026/01/30, 2026/02/27, 2026/03/27 | L12: 243
A13: 202508 | B13: Jul-Aug 2025 | C13: 313789.65 | D13: 0 | E13: 18933.81 | F13: 11114.4 | G13: 219386.27 | H13: 0 | I13: -124451.59 | J13: 2025/09/28 | K13: 2026/03/27, 2026/04/30 | L13: 214
A14: 202510 | B14: Sep-Oct 2025 | C14: 370625.28 | D14: 0 | E14: 37062.53 | F14: 972.9 | G14: 408660.71 | H14: 0 | I14: 0 | J14: 2025/11/25 | K14: 2025/11/29, 2026/02/06 | L14: 73
A15: 202512 | B15: Nov-Dec 2025 | C15: 96064.46 | D15: 0 | E15: 0 | F15: 0 | G15: 96064.46 | H15: 0 | I15: 0 | J15: 2026/01/26 | K15: 2026/01/30 | L15: 4
A16: 202602 | B16: Jan-Feb 2026 | C16: 373522.47 | D16: 0 | E16: 0 | F16: 0 | G16: 373522.47 | H16: 0 | I16: 0 | J16: 2026/03/27 | K16: 2026/03/27 | L16: 0
... A19: 202608 | B19: Jul-Aug 2026 | C19: 493396.01 | D19: 0 | E19: 34501.17 | F19: 2946.4 | G19: 382459.26 | H19: 0 | I19: -148384.32 | J19: 2026/09/17 | K19: 2026/10/07 | L19: 20

Sheet SH Enterprises VAT
A1: Safe Hub Enterprises (Pty) Ltd - VAT201 history (bi-monthly, periods ending Jan/Mar/May/Jul/Sep/Nov)
A2: Source: SARS VATSA statements of account issued 26 Oct 2026. Positive return = VAT payable. No payroll in this entity.
A4: Tax period (end) | B4: Period | C4: Return: payable (+) / refund (-) | D4: Additional assessment | E4: Penalty | F4: Interest | G4: Cash paid to SARS | H4: Refund received from SARS | I4: Set-off / journals | J4: Filed on | K4: Payment / refund date(s) | L4: Days from filing to cash
A5: 202403 | B5: Feb-Mar 2024 | C5: 365983.15 | D5: 0 | E5: 36598.32 | F5: 16078.16 | G5: 391209.53 | H5: -3288.76 | I5: -24161.34 | J5: 2024/04/29 | K5: 2024/06/27, 2024/06/30, 2024/07/31, 2024/08/30, 2024/09/30, 2024/10/30, 2024/11/27 | L5: 212
A6: 202405 | B6: Apr-May 2024 | C6: -3288.76 | D6: 0 | E6: 0 | F6: 0 | G6: 0 | H6: 3288.76 | I6: 0 | J6: 2024/06/28 | K6: 2024/06/30 | L6: 2
A7: 202407 | B7: Jun-Jul 2024 | C7: 307579.69 | D7: 0 | E7: 30757.97 | F7: 3011.21 | G7: 341348.87 | H7: 0 | I7: 0 | J7: 2024/08/30 | K7: 2024/09/16 | L7: 17
A8: 202409 | B8: Aug-Sep 2024 | C8: 296659.81 | D8: 0 | E8: 29665.98 | F8: 5808.6 | G8: 303559.96 | H8: 0 | I8: -28574.43 | J8: 2024/10/29 | K8: 2024/12/10 | L8: 42
A9: 202411 | B9: Oct-Nov 2024 | C9: 990136.99 | D9: 0 | E9: 99013.7 | F9: 57597.1 | G9: 1146747.8 | H9: 0 | I9: 0 | J9: 2024/12/31 | K9: 2025/03/31, 2025/05/06, 2025/06/03, 2025/06/25, 2025/07/31, 2025/08/13, 2025/09/30 | L9: 273
A10: 202501 | B10: Dec 2024-Jan 2025 | C10: 70541.17 | D10: 0 | E10: 0 | F10: 0 | G10: 70541.17 | H10: 0 | I10: 0 | J10: 2025/02/28 | K10: 2025/02/28 | L10: 0
A11: 202503 | B11: Feb-Mar 2025 | C11: 494929.76 | D11: 0 | E11: 49492.98 | F11: 4538.51 | G11: 548961.25 | H11: 0 | I11: 0 | J11: 2025/04/25 | K11: 2025/05/22 | L11: 27
A12: 202505 | B12: Apr-May 2025 | C12: 541187.28 | D12: 0 | E12: 54118.73 | F12: 23296.32 | G12: 618602.33 | H12: 0 | I12: 0 | J12: 2025/06/27 | K12: 2025/08/01, 2025/09/30, 2025/10/31, 2025/12/02, 2025/12/31, 2026/01/30 | L12: 217
A13: 202507 | B13: Jun-Jul 2025 | C13: 163265.99 | D13: 0 | E13: 16326.6 | F13: 8230.38 | G13: 187822.97 | H13: 0 | I13: 0 | J13: 2025/08/15 | K13: 2026/01/30, 2026/02/06 | L13: 175
A14: 202509 | B14: Aug-Sep 2025 | C14: 228418.83 | D14: 0 | E14: 0 | F14: 0 | G14: 228418.83 | H14: 0 | I14: 0 | J14: 2025/10/28 | K14: 2025/10/31 | L14: 3
A15: 202511 | B15: Oct-Nov 2025 | C15: 1144827.7 | D15: 0 | E15: 114482.77 | F15: 47354.24 | G15: 1306664.8 | H15: 0 | I15: 0 | J15: 2025/12/22 | K15: 2026/02/27, 2026/03/27, 2026/04/30, 2026/05/29, 2026/06/26, 2026/07/31 | L15: 221
A16: 202601 | B16: Dec 2025-Jan 2026 | C16: 121844.86 | D16: 0 | E16: 0 | F16: 0 | G16: 121844.86 | H16: 0 | I16: 0 | J16: 2026/02/24 | K16: 2026/02/27 | L16: 3
... A19: 202607 | B19: Jun-Jul 2026 | C19: 295145.81 | D19: 0 | E19: 0 | F19: 0 | G19: 295376.39 | H19: 230.58 | I19: 0 | J19: 2026/08/19 | K19: 2026/07/31, 2026/08/31, 2026/09/08 | L19: 20
A20: 202609 | B20: Aug-Sep 2026 | C20: 191492.58 | D20: 0 | E20: 19149.26 | F20: 0 | G20: 0 | H20: 0 | I20: 0 | J20: 2026/10/26

Sheet Amandla PAYE
A1: Amandla Social Enterprises - EMP201 history (PAYE, UIF, ETI; no SDL)
A2: Source: SARS EMPSOA statements of account, taxpayer ref 7260776309, issued 2026/10/26. Net EMP201 payable = PAYE + SDL + UIF - ETI utilised. Penalties/interest are what SARS raised for late payment.
A4: Tax period | B4: Payroll month | C4: PAYE | D4: SDL | E4: UIF | F4: ETI utilised | G4: Net EMP201 payable | H4: Penalty | I4: Interest | J4: Cash paid (incl pen/int) | K4: Payment date(s) | L4: ETI calculated | M4: ETI carried forward (balance owed by SARS)
A5: 202403 | B5: Mar 2024 | C5: 509735.07 | D5: 0 | E5: 19553.52 | F5: 0 | G5: =C5+D5+E5-F5 -> 529288.59 | H5: 0 | I5: 0 | J5: 529288.59 | K5: 2024/04/05 | L5: 3163.32 | M5: 3163.32
A6: 202404 | B6: Apr 2024 | C6: 555999.83 | D6: 0 | E6: 20854.22 | F6: 2062.5 | G6: =C6+D6+E6-F6 -> 574791.55 | H6: 57471.65 | I6: 12730.91 | J6: 0 | K6: settled by journal/credit | L6: 2062.5 | M6: 3163.32
A7: 202405 | B7: May 2024 | C7: 566175.35 | D7: 0 | E7: 20761.04 | F7: 0 | G7: =C7+D7+E7-F7 -> 586936.39 | H7: 58693.64 | I7: 14955.52 | J7: 383978.48 | K7: 2024/08/31, 2024/09/30, 2024/10/30 | L7: 683.32 | M7: 3846.64
A8: 202406 | B8: Jun 2024 | C8: 567901.29 | D8: 0 | E8: 21649.16 | F8: 0 | G8: =C8+D8+E8-F8 -> 589550.45 | H8: 58955.05 | I8: 32310.03 | J8: 679869.44 | K8: 2024/10/30, 2024/11/27, 2024/12/18, 2025/01/31 | L8: 0 | M8: 0
A9: 202407 | B9: Jul 2024 | C9: 600692.26 | D9: 0 | E9: 21338.62 | F9: 0 | G9: =C9+D9+E9-F9 -> 622030.88 | H9: 62203.09 | I9: 38830.69 | J9: 164510.75 | K9: 2025/01/31 | L9: 0 | M9: 0
A10: 202408 | B10: Aug 2024 | C10: 577332.39 | D10: 0 | E10: 21433.34 | F10: 0 | G10: =C10+D10+E10-F10 -> 598765.73 | H10: 59876.57 | I10: 57943.45 | J10: 24978.35 | K10: 2025/03/31 | L10: 1275 | M10: 0
A11: 202409 | B11: Sep 2024 | C11: 573547.24 | D11: 0 | E11: 21578.34 | F11: 0 | G11: =C11+D11+E11-F11 -> 595125.58 | H11: 59512.55 | I11: 63015.69 | J11: 25170.3 | K11: 2025/03/31, 2025/05/06 | L11: 1275 | M11: 1275
A12: 202410 | B12: Oct 2024 | C12: 572071.28 | D12: 0 | E12: 21162.22 | F12: 0 | G12: =C12+D12+E12-F12 -> 593233.5 | H12: 59323.35 | I12: 57194.48 | J12: 24743.23 | K12: 2025/05/06, 2025/06/25 | L12: 1275 | M12: 2550
A13: 202411 | B13: Nov 2024 | C13: 511932.63 | D13: 0 | E13: 20168.42 | F13: 3825 | G13: =C13+D13+E13-F13 -> 528276.05 | H13: 52827.6 | I13: 51664.51 | J13: 23583.86 | K13: 2025/06/25, 2025/07/31 | L13: 1275 | M13: 0
A14: 202412 | B14: Dec 2024 | C14: 524410.3 | D14: 0 | E14: 19603.9 | F14: 1275 | G14: =C14+D14+E14-F14 -> 542739.2 | H14: 54273.92 | I14: 53019.01 | J14: 270040.77 | K14: 2025/07/31, 2025/08/29, 2025/12/31 | L14: 1275 | M14: 0
A15: 202501 | B15: Jan 2025 | C15: 456085.8 | D15: 0 | E15: 18852.94 | F15: 1275 | G15: =C15+D15+E15-F15 -> 473663.74 | H15: 47366.37 | I15: 47070.08 | J15: 568100.19 | K15: 2025/08/29, 2025/12/31, 2026/01/30 | L15: 1275 | M15: 0
A16: 202502 | B16: Feb 2025 | C16: 459094.38 | D16: 0 | E16: 19209.32 | F16: 1650 | G16: =C16+D16+E16-F16 -> 476653.7 | H16: 47665.37 | I16: 47224.64 | J16: 571543.71 | K16: 2026/01/30, 2026/02/27 | L16: 1650 | M16: 0
... A35: 202609 | B35: Sep 2026 | C35: 605717.96 | D35: 0 | E35: 23159.66 | F35: 55715.83 | G35: =C35+D35+E35-F35 -> 573161.79 | H35: 0 | I35: 0 | J35: 573161.79 | K35: 2026/10/07 | L35: 55715.83 | M35: 0
A37: ETI cash refunds paid by SARS (end of each 6-month cycle):
A38: 2025/12/10 | B38: cycle to Aug 2025 | C38: 5225.73

Sheet Amandla VAT
A1: Amandla Social Enterprises - VAT201 history (monthly, refund position)
A2: Source: SARS VATSA statements of account issued 26 Oct 2026. Negative return = refund due to Amandla. "Set-off / journals" = refunds SARS applied against PAYE arrears (debt equalisation) in 2024-25 instead of paying cash.
A4: Tax period (end) | B4: Period | C4: Return: payable (+) / refund (-) | D4: Additional assessment | E4: Penalty | F4: Interest | G4: Cash paid to SARS | H4: Refund received from SARS | I4: Set-off / journals | J4: Filed on | K4: Payment / refund date(s) | L4: Days from filing to cash
A5: 202403 | B5: Mar 2024 | C5: -181092.16 | D5: 0 | E5: 0 | F5: 0 | G5: 0 | H5: 181092.16 | I5: 0 | J5: 2024/04/29 | K5: 2024/04/29 | L5: 0
A6: 202404 | B6: Apr 2024 | C6: -386237.43 | D6: 0 | E6: 0 | F6: 0 | G6: 0 | H6: 0 | I6: 386237.43 | J6: 2024/05/30
A7: 202405 | B7: May 2024 | C7: -535288.75 | D7: 0 | E7: 0 | F7: 0 | G7: 0 | H7: 0 | I7: 535288.75 | J7: 2024/06/28
A8: 202406 | B8: Jun 2024 | C8: -710585.18 | D8: 0 | E8: 0 | F8: 0 | G8: 0 | H8: 710585.18 | I8: 0 | J8: 2024/07/31 | K8: 2024/08/01 | L8: 1
A9: 202407 | B9: Jul 2024 | C9: -347117.34 | D9: 0 | E9: 0 | F9: 0 | G9: 0 | H9: 347117.34 | I9: 0 | J9: 2024/08/29 | K9: 2024/09/10 | L9: 12
A10: 202408 | B10: Aug 2024 | C10: -801069.13 | D10: 0 | E10: 0 | F10: 0 | G10: 0 | H10: 801069.13 | I10: 0 | J10: 2024/09/30 | K10: 2024/10/23 | L10: 23
A11: 202409 | B11: Sep 2024 | C11: -550161.2 | D11: 0 | E11: 0 | F11: 0 | G11: 0 | H11: 550161.2 | I11: 0 | J11: 2024/10/29 | K11: 2024/11/12 | L11: 14
A12: 202410 | B12: Oct 2024 | C12: -746662.85 | D12: 0 | E12: 0 | F12: 0 | G12: 0 | H12: 746662.85 | I12: 0 | J12: 2024/11/29 | K12: 2025/01/07 | L12: 39
A13: 202411 | B13: Nov 2024 | C13: -129445.8 | D13: 0 | E13: 0 | F13: 0 | G13: 0 | H13: 129445.8 | I13: 0 | J13: 2024/12/31 | K13: 2025/01/07 | L13: 7
A14: 202412 | B14: Dec 2024 | C14: -808264.18 | D14: 0 | E14: 0 | F14: 0 | G14: 0 | H14: 0 | I14: 808264.18 | J14: 2025/01/31
A15: 202501 | B15: Jan 2025 | C15: -579439.74 | D15: 0 | E15: 0 | F15: 0 | G15: 0 | H15: 579439.74 | I15: 0 | J15: 2025/02/28 | K15: 2025/03/12 | L15: 12
A16: 202502 | B16: Feb 2025 | C16: -226214 | D16: 0 | E16: 0 | F16: 0 | G16: 0 | H16: 0 | I16: 226214 | J16: 2025/03/30
A17: 202503 | B17: Mar 2025 | C17: -834655.79 | D17: 0 | E17: 0 | F17: 0 | G17: 0 | H17: 0 | I17: 834655.79 | J17: 2025/04/29
A18: 202504 | B18: Apr 2025 | C18: -144235.2 | D18: 0 | E18: 0 | F18: 0 | G18: 0 | H18: 0 | I18: 144235.2 | J18: 2025/05/28
A19: 202505 | B19: May 2025 | C19: -343437.7 | D19: 0 | E19: 0 | F19: 0 | G19: 0 | H19: 0 | I19: 343437.7 | J19: 2025/06/30
A20: 202506 | B20: Jun 2025 | C20: -361586 | D20: 0 | E20: 0 | F20: 0 | G20: 0 | H20: 0 | I20: 361586 | J20: 2025/07/28
A21: 202507 | B21: Jul 2025 | C21: -255174.84 | D21: 0 | E21: 0 | F21: 0 | G21: 0 | H21: 0 | I21: 255174.84 | J21: 2025/08/26
A22: 202508 | B22: Aug 2025 | C22: -383375.21 | D22: 0 | E22: 0 | F22: 0 | G22: 0 | H22: 0 | I22: 383375.21 | J22: 2025/09/29
A23: 202509 | B23: Sep 2025 | C23: -417374.13 | D23: 0 | E23: 0 | F23: 0 | G23: 0 | H23: 0 | I23: 417374.13 | J23: 2025/10/27
A24: 202510 | B24: Oct 2025 | C24: -454457.46 | D24: 0 | E24: 0 | F24: 0 | G24: 0 | H24: 454457.46 | I24: 0 | J24: 2025/11/25 | K24: 2026/01/19 | L24: 55
A25: 202511 | B25: Nov 2025 | C25: -366017.3 | D25: 0 | E25: 0 | F25: 0 | G25: 0 | H25: 366017.3 | I25: 0 | J25: 2025/12/19 | K25: 2025/12/21 | L25: 2
A26: 202512 | B26: Dec 2025 | C26: -491610.15 | D26: 0 | E26: 0 | F26: 0 | G26: 0 | H26: 491610.15 | I26: 0 | J26: 2026/01/26 | K26: 2026/01/27 | L26: 1
A27: 202601 | B27: Jan 2026 | C27: -344919.32 | D27: 0 | E27: 0 | F27: 0 | G27: 0 | H27: 344919.32 | I27: 0 | J27: 2026/02/24 | K27: 2026/02/24 | L27: 0
A28: 202602 | B28: Feb 2026 | C28: -579213.16 | D28: 0 | E28: 0 | F28: 0 | G28: 0 | H28: 579213.16 | I28: 0 | J28: 2026/03/27 | K28: 2026/04/01 | L28: 5
A29: 202603 | B29: Mar 2026 | C29: -401978.93 | D29: 0 | E29: 0 | F29: 0 | G29: 0 | H29: 401978.93 | I29: 0 | J29: 2026/04/23 | K29: 2026/04/23 | L29: 0
A30: 202604 | B30: Apr 2026 | C30: -587749.27 | D30: 0 | E30: 0 | F30: 0 | G30: 0 | H30: 587749.27 | I30: 0 | J30: 2026/05/26 | K30: 2026/05/26 | L30: 0
A31: 202605 | B31: May 2026 | C31: -309416.27 | D31: 0 | E31: 0 | F31: 0 | G31: 0 | H31: 309416.27 | I31: 0 | J31: 2026/06/23 | K31: 2026/06/23 | L31: 0
A32: 202606 | B32: Jun 2026 | C32: -411945.3 | D32: 0 | E32: 0 | F32: 0 | G32: 0 | H32: 411945.3 | I32: 0 | J32: 2026/07/21 | K32: 2026/07/21 | L32: 0
A33: 202607 | B33: Jul 2026 | C33: -468173.56 | D33: 0 | E33: 0 | F33: 0 | G33: 0 | H33: 468173.56 | I33: 0 | J33: 2026/08/18 | K33: 2026/08/18 | L33: 0
A34: 202608 | B34: Aug 2026 | C34: -761958.59 | D34: 0 | E34: 0 | F34: 0 | G34: 0 | H34: 761958.59 | I34: 0 | J34: 2026/09/17 | K34: 2026/10/15 | L34: 28
A35: 202609 | B35: Sep 2026 | C35: -598538.79 | D35: 0 | E35: 0 | F35: 0 | G35: 0 | H35: 598538.79 | I35: 0 | J35: 2026/10/26 | K35: 2026/10/26 | L35: 0
